Workbook

Sheet MENU
B2: MENU
B4: Supuestos Generales | D4: Cuentas Estado de Resultados | F4: Cuentas Estado de Situación Financiera
B6: Supuestos | D6: Ventas | F6: IME
D7: Costo de Ventas | F7: Fondo de Maniobra
B8: Estados Financieros | D8: Gasto de Personal | F8: Otras cuentas del activo
D9: Gasto de Ventas | F9: Pasivo por Arrendamiento
B10: Estado de Resultados | D10: Gasto de Administración
B11: Estado de Situación Financiera | D11: Ingresos Financieros | F11: Cuentas Estado de Flujo de Efectivo
B12: Estado de Cambios de Patrimonio | D12: Gastos Financieros
B13: Estado de Flujos de Efectivo | D13: Otros Gastos | F13: Fuentes Usos
D14: IR + PT

Sheet Supuestos
B2: SUPUESTOS PARA EL ESTADO DE RESULTADOS | F2: SUPUESTOS PARA EL ESTADO DE SITUACIÓN FINANCIERA
B4: VENTAS | D4: Valor Historico | F4: FONDO DE MANIOBRA | H4: Valor Historico | K4: ESCENARIOS
B5: Ventas Nacionales | C5: =L13 -> 0.0108 | D5: =L19 -> 0.010847322 | F5: Periodo Promedio de Inv (PPI) | G5: 48 | H5: =+AVERAGE('Fondo Maniobra'!D23:G23) -> 47.941332
B6: Ventas Exterior | C6: =M13 -> -0.0761 | D6: =M19 -> -0.076101832 | F6: Periodo Promedio de CxC (PPC) | G6: 23 | H6: =+AVERAGE('Fondo Maniobra'!D13:G13) -> 23.398755 | K6: Escenario | L6: 2
B7: Ventas a partes relacionadas | C7: =N13 -> 0.1315 | D7: =N19 -> 0.13154213 | F7: Periodo Promedio de CxP (PPP) | G7: 107 | H7: =+AVERAGE('Fondo Maniobra'!B40:G40) -> 107.15174
G8: =+G5+G6-G7 -> -36 | L8: Tasa de Crecimiento de Ventas
B9: COSTO DE VENTAS | D9: Valor Historico | L9: Nacionales | M9: Exterior | N9: Relacionados
B10: Costo de Ventas Sin Gasto Personal | C10: 0.8513 | D10: =+AVERAGE('Costo de Ventas'!C15:H15)/AVERAGE('Costo de Ventas'!C5:H5) -> 0.85134539 | F10: FACTORING/CxP | G10: 0.8374 | H10: =+AVERAGE('Fondo Maniobra'!B43:G43)/AVERAGE('Fondo Maniobra'!B37:G37) -> 0.83736439 | K10: Optimista | L10: 0.05 | M10: 0.25 | N10: 0.53
K11: Base | L11: 0.0108 | M11: -0.0761 | N11: 0.1315
B12: GASTOS DE PERSONAL | D12: Valor Historico | F12: COBRANZA A ENTIDADES RELACIONADAS | K12: Pesimista | L12: 0 | M12: 0 | N12: 0
K13: Escenario | L13: =CHOOSE($L$6,L10,L11,L12) -> 0.0108 | M13: =CHOOSE($L$6,M10,M11,M12) -> -0.0761 | N13: =CHOOSE($L$6,N10,N11,N12) -> 0.1315
B14: Gastos de Personal | C14: 0.014 | D14: =+'Gasto de Personal'!G17 -> 0.013961305 | G14: 2025 | H14: 2026 | I14: 2027
F15: Cobranza a Entidades Relacionadas | G15: 56056 | L15: Nacionales | M15: Exterior | N15: Relacionados
B16: Gratificaciones | C16: 0.2178 | D16: =+'Gasto de Personal'!G33 -> 0.21777003 | K16: Optimista | L16: =Ventas!N5 -> 0.050610047 | M16: =Ventas!N6 -> 0.25420357 | N16: =Ventas!N7 -> 0.53781355
B17: CTS | C17: 0.1205 | D17: =+'Gasto de Personal'!G34 -> 0.12052582 | F17: OTRAS CXC | H17: Valor Historico | K17: Base | L17: =Ventas!O5 -> 0.010847322 | M17: =Ventas!O6 -> -0.076101832 | N17: =Ventas!O7 -> 0.13154213
B18: Contribuciones sociales | C18: 0.0939 | D18: =+'Gasto de Personal'!G35 -> 0.093918277 | F18: Otras Cuentas por Cobrar | G18: 0.0266 | H18: =+AVERAGE(Otros!B13:G13)/AVERAGE(Otros!B12:G12) -> 0.026579816 | K18: Pesimista | L18: 0 | M18: 0 | N18: 0
B19: Vacaciones | C19: 0.1082 | D19: =+'Gasto de Personal'!G36 -> 0.10817232 | K19: Escenario | L19: =CHOOSE($L$6,L16,L17,L18) -> 0.010847322 | M19: =CHOOSE($L$6,M16,M17,M18) -> -0.076101832 | N19: =CHOOSE($L$6,N16,N17,N18) -> 0.13154213
B20: Otros | C20: 0.4487 | D20: =+'Gasto de Personal'!G37 -> 0.44868546 | F20: IME | H20: Valor Historico
F21: Adiciones | G21: 0.0082 | H21: =+AVERAGE(IME!B11:G11)/AVERAGE(IME!B5:G5) -> 0.0082332942 | I21: Ventas | K21: RESULTADOS
B22: Tasa Asignación Gasto de Personal | D22: Valor Historico
B23: Costo de Ventas | C23: 0.6418 | D23: =+'Gasto de Personal'!G26 -> 0.64177778 | G23: 2025 | H23: 2026 | I23: 2027 | L23: 2025 | M23: 2026 | N23: 2027
B24: Gasto de Ventas | C24: 0.193 | D24: =+'Gasto de Personal'!G27 -> 0.19301587 | F24: Venta de Activo | G24: 0 | H24: 0 | I24: 0 | K24: Ventas | L24: =ER!H6 -> 470950.02 | M24: =ER!I6 -> 493161.32 | N24: =ER!J6 -> 519243.42
B25: Gasto de Administración | C25: 0.1652 | D25: =+'Gasto de Personal'!G28 -> 0.16520635 | K25: EBITDA | L25: =ER!H13+IME!H14 -> 36319.03 | M25: =ER!I13+IME!I14 -> 38192.497 | N25: =ER!J13+IME!J14 -> 40350.103
C26: =+SUM(C23:C25) -> 1 | F26: Activos por Derecho de Uso | H26: Valor Historico | K26: NOPAT | L26: =ER!H13*(1-'IR PT'!H24) -> 21899.612 | M26: =ER!I13*(1-'IR PT'!I24) -> 22958.443 | N26: =ER!J13*(1-'IR PT'!J24) -> 24197.626
F27: Activos por Derecho de Uso | G27: 0.0229 | H27: =+AVERAGE(IME!B34:G34)/AVERAGE(IME!B5:G5) -> 0.022903692 | I27: Ventas
B28: GASTO DE VENTAS | D28: Valor Historico | F28: Depreciación Act por Derecho de Uso | G28: 2799 | H28: =IME!G33 -> 2799 | I28: Ventas | K28: Resultado Ejercicio | L28: =ER!H19 -> 25323.442 | M28: =ER!I19 -> 26497.79 | N28: =ER!J19 -> 27939.59
B29: Servicios Recibidos | C29: 0.0111 | D29: =+AVERAGE('Gasto de Ventas'!B8:G8)/AVERAGE('Gasto de Ventas'!B5:G5) -> 0.011059963 | F29: % Asignación Gasto Administración | G29: 0.7 | H29: =IME!G37 -> 0.6952483
B30: Cargas diversas de gestión | C30: 0.0021 | D30: =+AVERAGE('Gasto de Ventas'!B10:G10)/AVERAGE('Gasto de Ventas'!B5:G5) -> 0.0021436953 | F30: % Asignación Gasto de Ventas | G30: 0.3 | H30: =IME!G38 -> 0.3047517 | K30: Total Activos | L30: =ESF!H24 -> 226045.44 | M30: =ESF!I24 -> 248614.32 | N30: =ESF!J24 -> 253578.88
K31: Total Pasivos | L31: =ESF!H40 -> 139323.46 | M31: =ESF!I40 -> 157355.93 | N31: =ESF!J40 -> 157537.22
B32: GASTO DE ADMINISTRACIÓN | D32: Valor Historico | F32: INVERSIONES EN SUBSIDIARIAS | K32: Total Patrimonio | L32: =ESF!H48 -> 86721.973 | M32: =ESF!I48 -> 91258.395 | N32: =ESF!J48 -> 96041.653
B33: Servicios Recibidos | C33: 0.0193 | D33: =+AVERAGE('Gasto de Administración'!B9:G9)/AVERAGE('Gasto de Administración'!$B$5:$G$5) -> 0.019291252
B34: Cargas diversas de gestión | C34: 0.0032 | D34: =+AVERAGE('Gasto de Administración'!B12:G12)/AVERAGE('Gasto de Administración'!$B$5:$G$5) -> 0.0031731705 | G34: 2025 | H34: 2026 | I34: 2027 | K34: Total Activo Cte | L34: =ESF!H15 -> 172034.85 | M34: =ESF!I15 -> 191900.47 | N34: =ESF!J15 -> 194055.23
B35: Provisiones por perdida crediticia | C35: 148 | D35: =+AVERAGE('Gasto de Administración'!B16:G16) -> 148 | F35: Variaciones | G35: 0 | H35: 0 | I35: 0 | K35: Total Pasivo Cte | L35: =ESF!H34 -> 131630.14 | M35: =ESF!I34 -> 149299.76 | N35: =ESF!J34 -> 149054.99
B37: DEPRECIACIÓN | D37: Valor Historico | F37: ARRENDAMIENTOS | H37: Valor Historico | K37: Caja y equivalentes | L37: =+ESF!H8 -> 63953.699 | M37: =+ESF!I8 -> 82164.158 | N37: =+ESF!J8 -> 75270.962
B38: Depreciación Anual | C38: 0.0893 | D38: =+AVERAGE(IME!B14:G14)/AVERAGE(IME!B8:G8) -> 0.089267431 | F38: Pasivo por arrendamiento | G38: 0.0248 | H38: =+AVERAGE('Pasivo Arrendamiento'!B11:G11)/AVERAGE('Pasivo Arrendamiento'!B5:G5) -> 0.024785129 | K38: Dividendos | L38: =+'Cambios Patrimonio'!H22 -> 20988.069 | M38: =+'Cambios Patrimonio'!I22 -> 21961.369 | N38: =+'Cambios Patrimonio'!J22 -> 23156.332
F39: % Porción Cte | G39: 0.3413 | H39: =+AVERAGE('Pasivo Arrendamiento'!B9:G9)/AVERAGE('Pasivo Arrendamiento'!B11:G11) -> 0.34125073
B40: Tasa Asignación Depreciación | K40: ROA | L40: =L26/L30 -> 0.096881459 | M40: =M26/M30 -> 0.092345618 | N40: =N26/N30 -> 0.095424456
B41: Costo de Ventas | C41: 0.8964 | D41: =+IME!G26 -> 0.89640965 | K41: ROE | L41: =L28/L32 -> 0.29200722 | M41: =M28/M32 -> 0.29036003 | N41: =N28/N32 -> 0.29091117
B42: Gasto de Ventas | C42: 0.0309 | D42: =+IME!G27 -> 0.03090053 | F42: OTRAS CUENTAS POR PAGAR | H42: Valor Historico | K42: ROS | L42: =L28/L24 -> 0.053770976 | M42: =M28/M24 -> 0.053730472 | N42: =N28/N24 -> 0.053808269
B43: Gasto de Administración | C43: 0.0727 | D43: =+IME!G28 -> 0.072689818 | F43: Saldo | G43: 6739 | H43: =+ESF!G32 -> 6739
...

Sheet ER
A4: INDECO S.A.ESTADOS FINANCIEROS
A5: CUENTA | B5: 2019 | C5: 2020 | D5: 2021 | E5: 2022 | F5: 2023 | G5: 2024 | H5: 2025 | I5: 2026 | J5: 2027
A6: Ingresos de actividades ordinarias | B6: 199619 | C6: 187321 | D6: 330211 | E6: 424158 | F6: 400661 | G6: 452250 | H6: =+Ventas!I8 -> 470950.02 | I6: =+Ventas!J8 -> 493161.32 | J6: =+Ventas!K8 -> 519243.42
A7: Costo de Ventas | B7: -166246 | C7: -161990 | D7: -290126 | E7: -373656 | F7: -355059 | G7: -405000 | H7: =-'Costo de Ventas'!I8 -> -412004.76 | I7: =-'Costo de Ventas'!J8 -> -431433.94 | J7: =-'Costo de Ventas'!K8 -> -454255.68
A8: Ganancia (Pérdida) Bruta | B8: =+SUM(B6:B7) -> 33373 | C8: =+SUM(C6:C7) -> 25331 | D8: =+SUM(D6:D7) -> 40085 | E8: =+SUM(E6:E7) -> 50502 | F8: =+SUM(F6:F7) -> 45602 | G8: =+SUM(G6:G7) -> 47250 | H8: =+SUM(H6:H7) -> 58945.255 | I8: =+SUM(I6:I7) -> 61727.381 | J8: =+SUM(J6:J7) -> 64987.735
A9: Gastos de Ventas y Distribución | B9: -7268 | C9: -6041 | D9: -8061 | E9: -10227 | F9: -8903 | G9: -8553 | H9: =-'Gasto de Ventas'!H15 -> -10476.034 | I9: =-'Gasto de Ventas'!I15 -> -10931.903 | J9: =-'Gasto de Ventas'!J15 -> -11468.102
A10: Gastos de Administración | B10: -10010 | C10: -9714 | D10: -11817 | E10: -13786 | F10: -14667 | G10: -13249 | H10: =-'Gasto de Administración'!H17 -> -15928.767 | I10: =-'Gasto de Administración'!I17 -> -16576.895 | J10: =-'Gasto de Administración'!J17 -> -17337.078
A11: Otros Ingresos Operativos | B11: 1430 | C11: 1875 | D11: 1341 | E11: 850 | F11: 5634 | G11: 1881 | H11: =+Supuestos!$C$47 -> 2169 | I11: =+Supuestos!$C$47 -> 2169 | J11: =+Supuestos!$C$47 -> 2169
A12: Otros Gastos Operativos | B12: -11 | C12: -10 | D12: -41 | E12: -50 | F12: -36 | G12: -34 | H12: =-'Otros Gastos Op'!H8 -> -42.385501 | I12: =-'Otros Gastos Op'!I8 -> -44.384518 | J12: =-'Otros Gastos Op'!J8 -> -46.731907
A13: Ganancia (Pérdida) por actividades de operación | B13: =+SUM(B8:B12) -> 17514 | C13: =+SUM(C8:C12) -> 11441 | D13: =+SUM(D8:D12) -> 21507 | E13: =+SUM(E8:E12) -> 27289 | F13: =+SUM(F8:F12) -> 27630 | G13: =+SUM(G8:G12) -> 27295 | H13: =+SUM(H8:H12) -> 34667.069 | I13: =+SUM(I8:I12) -> 36343.198 | J13: =+SUM(J8:J12) -> 38304.824
A14: Ingresos Financieros | B14: 386 | C14: 843 | D14: 2507 | E14: 1351 | F14: 4855 | G14: 5148 | H14: =+'Ing Financieros'!H5 -> 3062.3591 | I14: =+'Ing Financieros'!I5 -> 3129.0116 | J14: =+'Ing Financieros'!J5 -> 3302.981
A15: Gastos Financieros | B15: -976 | C15: -1187 | D15: -814 | E15: -1449 | F15: -1337 | G15: -1106 | H15: =-'Gasto Financiero'!H5 -> -1623.4589 | I15: =-'Gasto Financiero'!I5 -> -1700.0257 | J15: =-'Gasto Financiero'!J5 -> -1789.9359
A16: Diferencias de Cambio neto | B16: -94 | C16: -565 | D16: -1076 | E16: 347 | F16: 297 | G16: 37 | H16: =+Supuestos!$C$51 -> -176 | I16: =+Supuestos!$C$51 -> -176 | J16: =+Supuestos!$C$51 -> -176
A17: Resultado antes de Impuesto a las Ganancias | B17: =+SUM(B13:B16) -> 16830 | C17: =+SUM(C13:C16) -> 10532 | D17: =+SUM(D13:D16) -> 22124 | E17: =+SUM(E13:E16) -> 27538 | F17: =+SUM(F13:F16) -> 31445 | G17: =+SUM(G13:G16) -> 31374 | H17: =+SUM(H13:H16) -> 35929.969 | I17: =+SUM(I13:I16) -> 37596.184 | J17: =+SUM(J13:J16) -> 39641.869
A18: Ingreso (Gasto) por Impuesto | B18: -5165 | C18: -4347 | D18: -7876 | E18: -7188 | F18: -7475 | G18: -9227 | H18: =-H17*Supuestos!$C$55 -> -10606.527 | I18: =-I17*Supuestos!$C$55 -> -11098.394 | J18: =-J17*Supuestos!$C$55 -> -11702.28
A19: Ganancia (Pérdida) Neta del Ejercicio | B19: =+SUM(B17:B18) -> 11665 | C19: =+SUM(C17:C18) -> 6185 | D19: =+SUM(D17:D18) -> 14248 | E19: =+SUM(E17:E18) -> 20350 | F19: =+SUM(F17:F18) -> 23970 | G19: =+SUM(G17:G18) -> 22147 | H19: =+SUM(H17:H18) -> 25323.442 | I19: =+SUM(I17:I18) -> 26497.79 | J19: =+SUM(J17:J18) -> 27939.59
B20: =-B18/B17 -> 0.30689245 | C20: =-C18/C17 -> 0.41274212 | D20: =-D18/D17 -> 0.35599349 | E20: =-E18/E17 -> 0.26102113 | F20: =-F18/F17 -> 0.23771665 | G20: =-G18/G17 -> 0.29409702

Sheet ESF
A4: INDECO S.A.ESTADOS FINANCIEROS
A5: CUENTA | B5: 2019 | C5: 2020 | D5: 2021 | E5: 2022 | F5: 2023 | G5: 2024 | H5: 2025 | I5: 2026 | J5: 2027
A6: Activos
A7: Activos Corrientes
A8: Efectivo y Equivalentes al Efectivo | B8: 12187 | C8: 21730 | D8: 27527 | E8: 27157 | F8: 32684 | G8: 17790 | H8: =+H40+H48-H23-SUM(H9:H14) -> 63953.699 | I8: =I49-I23-SUM(I9:I14) -> 82164.158 | J8: =J49-J23-SUM(J9:J14) -> 75270.962
A9: Cuentas por Cobrar Comerciales | B9: 24037 | C9: 17377 | D9: 28388 | E9: 26997 | F9: 25283 | G9: 29131 | H9: =+'Fondo Maniobra'!H10 -> 31045.946 | I9: =+'Fondo Maniobra'!I10 -> 31969.111 | J9: =+'Fondo Maniobra'!J10 -> 34378.659
A10: Cuentas por Cobrar a Entidades Relacionadas | B10: 23597 | C10: 21589 | D10: 19573 | E10: 53628 | F10: 66550 | G10: 62623 | H10: =+Otros!H7 -> 6567 | I10: =+Otros!I7 -> 6567 | J10: =+Otros!J7 -> 6567
A11: Otras Cuentas por Cobrar | B11: 3367 | C11: 4791 | D11: 7889 | E11: 13573 | F11: 8319 | G11: 15067 | H11: =+Otros!H13 -> 12527.27 | I11: =+Otros!I13 -> 13118.091 | J11: =+Otros!J13 -> 13811.875
A12: Inventarios | B12: 28952 | C12: 31043 | D12: 45809 | E12: 57367 | F12: 44150 | G12: 52414 | H12: =+'Fondo Maniobra'!H20 -> 57453.936 | I12: =+'Fondo Maniobra'!I20 -> 57595.113 | J12: =+'Fondo Maniobra'!J20 -> 63539.735
A13: Activos por Impuestos a las Ganancias | B13: 0 | C13: 0 | D13: 0 | E13: 354 | F13: 629 | G13: 480 | H13: =+G13 -> 480 | I13: =+H13 -> 480 | J13: =+I13 -> 480
A14: Gastos pagados por anticipado | B14: 97 | C14: 63 | D14: 215 | E14: 112 | F14: 76 | G14: 7 | H14: =+G14 -> 7 | I14: =+H14 -> 7 | J14: =+I14 -> 7
A15: Total Activos Corrientes | B15: =+SUM(B8:B14) -> 92237 | C15: =+SUM(C8:C14) -> 96593 | D15: =+SUM(D8:D14) -> 129401 | E15: =+SUM(E8:E14) -> 179188 | F15: =+SUM(F8:F14) -> 177691 | G15: =+SUM(G8:G14) -> 177512 | H15: =+SUM(H8:H14) -> 172034.85 | I15: =+SUM(I8:I14) -> 191900.47 | J15: =+SUM(J8:J14) -> 194055.23
A16: Activos No Corrientes
A17: Inversiones en subsidiarias, negocios conjuntos y asociadas | B17: 2080 | C17: 11016 | D17: 10991 | E17: 11074 | F17: 11151 | G17: 11369 | H17: =+Otros!H18 -> 11369 | I17: =+Otros!I18 -> 11369 | J17: =+Otros!J18 -> 11369
A18: Propiedades de Inversión | B18: 879 | C18: 0 | D18: 0 | E18: 0 | G18: 10769 | H18: =+G18 -> 10769 | I18: =+H18 -> 10769 | J18: =+I18 -> 10769
A19: Propiedades, Planta y Equipo | B19: 37597 | C19: 27160 | D19: 26929 | E19: 29140 | F19: 29112 | G19: 18499 | H19: =+IME!H16 -> 20708.829 | I19: =+IME!I16 -> 22903.454 | J19: =+IME!J16 -> 25115.971
A20: Activos Intangibles Distintos de la Plusvalía | B20: 60 | C20: 32 | D20: 24 | E20: 28 | F20: 59 | G20: 379 | H20: =+G20 -> 379 | I20: =+H20 -> 379 | J20: =+I20 -> 379
A21: Activos por Impuestos Diferidos | B21: 0 | C21: 0 | D21: 0 | E21: 616 | F21: 1406 | G21: 773 | H21: 0 | I21: 0 | J21: 0
A22: Otros Activos no financieros | B22: 3716 | C22: 8839 | D22: 5945 | E22: 8258 | F22: 5590 | G22: 13327 | H22: =+IME!H34 -> 10784.755 | I22: =+IME!I34 -> 11293.394 | J22: =+IME!J34 -> 11890.674
A23: Total Activos No Corrientes | B23: =+SUM(B17:B22) -> 44332 | C23: =+SUM(C17:C22) -> 47047 | D23: =+SUM(D17:D22) -> 43889 | E23: =+SUM(E17:E22) -> 49116 | F23: =+SUM(F17:F22) -> 47318 | G23: =+SUM(G17:G22) -> 55116 | H23: =+SUM(H17:H22) -> 54010.585 | I23: =+SUM(I17:I22) -> 56713.848 | J23: =+SUM(J17:J22) -> 59523.646
A24: TOTAL DE ACTIVOS | B24: =+B23+B15 -> 136569 | C24: =+C23+C15 -> 143640 | D24: =+D23+D15 -> 173290 | E24: =+E23+E15 -> 228304 | F24: =+F23+F15 -> 225009 | G24: =+G23+G15 -> 232628 | H24: =+H23+H15 -> 226045.44 | I24: =+I23+I15 -> 248614.32 | J24: =+J23+J15 -> 253578.88
A26: Pasivos y Patrimonio
A27: Pasivos Corrientes
A28: Otros Pasivos Financieros | B28: 15 | C28: 20 | D28: 1241 | E28: 37 | F28: 7 | G28: 0 | H28: =+G28 -> 0 | I28: =+H28 -> 0 | J28: =+I28 -> 0
A29: Factoring con proveedores | B29: 42680 | C29: 45104 | D29: 63905 | E29: 110118 | F29: 109401 | G29: 104317 | H29: =+'Fondo Maniobra'!H43 -> 100096.85 | I29: =+'Fondo Maniobra'!I43 -> 114735.96 | J29: =+'Fondo Maniobra'!J43 -> 114346.12
A30: Cuentas por Pagar Comerciales | B30: 5179 | C30: 8756 | D30: 20232 | E30: 20249 | F30: 13882 | G30: 24060 | H30: =+'Fondo Maniobra'!H44 -> 19436.05 | I30: =+'Fondo Maniobra'!I44 -> 22278.562 | J30: =+'Fondo Maniobra'!J44 -> 22202.865
A31: Cuentas por Pagar a Entidades Relacionadas | B31: 1487 | C31: 1222 | D31: 944 | E31: 946 | F31: 4120 | G31: 1372 | H31: =+G31 -> 1372 | I31: =+H31 -> 1372 | J31: =+I31 -> 1372
A32: Otras Cuentas por Pagar | B32: 6440 | C32: 5854 | D32: 6531 | E32: 7475 | F32: 7116 | G32: 6739 | H32: =+Supuestos!$G$43 -> 6739 | I32: =+Supuestos!$G$43 -> 6739 | J32: =+Supuestos!$G$43 -> 6739
A33: Pasivos por arrendamientos | B33: 875 | C33: 4076 | D33: 3088 | E33: 2781 | F33: 3019 | G33: 3028 | H33: =+'Pasivo Arrendamiento'!H9 -> 3986.234 | I33: =+'Pasivo Arrendamiento'!I9 -> 4174.2357 | J33: =+'Pasivo Arrendamiento'!J9 -> 4395.0009
A34: Total Pasivos Corrientes | B34: =+SUM(B28:B33) -> 56676 | C34: =+SUM(C28:C33) -> 65032 | D34: =+SUM(D28:D33) -> 95941 | E34: =+SUM(E28:E33) -> 141606 | F34: =+SUM(F28:F33) -> 137545 | G34: =+SUM(G28:G33) -> 139516 | H34: =+SUM(H28:H33) -> 131630.14 | I34: =+SUM(I28:I33) -> 149299.76 | J34: =+SUM(J28:J33) -> 149054.99
A35: Pasivos No Corrientes
A36: Otros Pasivos Financieros | B36: 4 | C36: 69 | D36: 87 | E36: 20 | F36: 0 | H36: =+G36 -> 0 | I36: =+H36 -> 0 | J36: =+I36 -> 0
A37: Pasivos por arrendamientos | B37: 2934 | C37: 6246 | D37: 3237 | E37: 6168 | F37: 3250 | G37: 10725 | H37: =+'Pasivo Arrendamiento'!H10 -> 7693.3264 | I37: =+'Pasivo Arrendamiento'!I10 -> 8056.1649 | J37: =+'Pasivo Arrendamiento'!J10 -> 8482.2358
A38: Pasivos por impuestos diferidos | B38: 1152 | C38: 753 | D38: 1311 | E38: 0 | F38: 0 | H38: =+G38 -> 0 | I38: =+H38 -> 0 | J38: =+I38 -> 0
A39: Total Pasivos No Corrientes | B39: =+SUM(B36:B38) -> 4090 | C39: =+SUM(C36:C38) -> 7068 | D39: =+SUM(D36:D38) -> 4635 | E39: =+SUM(E36:E38) -> 6188 | F39: =+SUM(F36:F38) -> 3250 | G39: =+SUM(G36:G38) -> 10725 | H39: =+SUM(H36:H38) -> 7693.3264 | I39: =+SUM(I36:I38) -> 8056.1649 | J39: =+SUM(J36:J38) -> 8482.2358
A40: Total Pasivos | B40: =+B39+B34 -> 60766 | C40: =+C39+C34 -> 72100 | D40: =+D39+D34 -> 100576 | E40: =+E39+E34 -> 147794 | F40: =+F39+F34 -> 140795 | G40: =+G39+G34 -> 150241 | H40: =+H39+H34 -> 139323.46 | I40: =+I39+I34 -> 157355.93 | J40: =+J39+J34 -> 157537.22
A42: Patrimonio
A43: Capital Emitido | B43: 53998 | C43: 53998 | D43: 53998 | E43: 53998 | F43: 53998 | G43: 53998 | H43: =+'Cambios Patrimonio'!H6 -> 53998 | I43: =+'Cambios Patrimonio'!I6 -> 53998 | J43: =+'Cambios Patrimonio'!J6 -> 53998
A44: Acciones de Inversión | B44: 1585 | C44: 1585 | D44: 1585 | E44: 1585 | F44: 1585 | G44: 1585 | H44: =+G44 -> 1585 | I44: =+H44 -> 1585 | J44: =+I44 -> 1585
A45: Otras Reservas de Capital | B45: 10800 | C45: 10800 | D45: 10800 | E45: 10800 | F45: 10800 | G45: 10800 | H45: =+'Cambios Patrimonio'!H15 -> 10799.6 | I45: =+'Cambios Patrimonio'!I15 -> 10799.6 | J45: =+'Cambios Patrimonio'!J15 -> 10799.6
...

Sheet Cambios Patrimonio
A4: PATRIMONIO
B5: 2019 | C5: 2020 | D5: 2021 | E5: 2022 | F5: 2023 | G5: 2024 | H5: 2025 | I5: 2026 | J5: 2027
A6: Saldo | B6: =+ESF!B43 -> 53998 | C6: =+ESF!C43 -> 53998 | D6: =+ESF!D43 -> 53998 | E6: =+ESF!E43 -> 53998 | F6: =+ESF!F43 -> 53998 | G6: =+ESF!G43 -> 53998 | H6: =+G6+H7 -> 53998 | I6: =+H6+I7 -> 53998 | J6: =+I6+J7 -> 53998
A7: Variaciones Capital | H7: =+Supuestos!G54 -> 0 | I7: =+Supuestos!H54 -> 0 | J7: =+Supuestos!I54 -> 0
A9: Relacionado con la Reserva Legal
B10: 2019 | C10: 2020 | D10: 2021 | E10: 2022 | F10: 2023 | G10: 2024 | H10: 2025 | I10: 2026 | J10: 2027
A11: Ganancia (Pérdida) Neta del Ejercicio | B11: =+ER!B19 -> 11665 | C11: =+ER!C19 -> 6185 | D11: =+ER!D19 -> 14248 | E11: =+ER!E19 -> 20350 | F11: =+ER!F19 -> 23970 | G11: =+ER!G19 -> 22147 | H11: =+ER!H19 -> 25323.442 | I11: =+ER!I19 -> 26497.79 | J11: =+ER!J19 -> 27939.59
A12: Capital Emitido | B12: =+ESF!B43 -> 53998 | C12: =+ESF!C43 -> 53998 | D12: =+ESF!D43 -> 53998 | E12: =+ESF!E43 -> 53998 | F12: =+ESF!F43 -> 53998 | G12: =+ESF!G43 -> 53998 | H12: =+ESF!H43 -> 53998 | I12: =+ESF!I43 -> 53998 | J12: =+ESF!J43 -> 53998
A13: Reserva Legal Teorica | H13: =+G11*Supuestos!$G$47 -> 2214.7 | I13: =+H11*Supuestos!$G$47 -> 2532.3442 | J13: =+I11*Supuestos!$G$47 -> 2649.779
A14: Reserva Legal Máxima | H14: =G12*Supuestos!$G$48 -> 10799.6 | I14: =H12*Supuestos!$G$48 -> 10799.6 | J14: =I12*Supuestos!$G$48 -> 10799.6
A15: =+ESF!A45 -> Otras Reservas de Capital | B15: =+ESF!B45 -> 10800 | C15: =+ESF!C45 -> 10800 | D15: =+ESF!D45 -> 10800 | E15: =+ESF!E45 -> 10800 | F15: =+ESF!F45 -> 10800 | G15: =+ESF!G45 -> 10800 | H15: =MIN(G15+H13,H14) -> 10799.6 | I15: =MIN(H15+I13,I14) -> 10799.6 | J15: =MIN(I15+J13,J14) -> 10799.6
B16: =B15/B12 -> 0.20000741 | C16: =C15/C12 -> 0.20000741 | D16: =D15/D12 -> 0.20000741 | E16: =E15/E12 -> 0.20000741 | F16: =F15/F12 -> 0.20000741 | G16: =G15/G12 -> 0.20000741
A18: Relacionado con el resultado acumulado
B19: 2019 | C19: 2020 | D19: 2021 | E19: 2022 | F19: 2023 | G19: 2024 | H19: 2025 | I19: 2026 | J19: 2027
A20: Saldo Inicial | B20: 7651 | C20: =+B23 -> 9420 | D20: =+C23 -> 5157 | E20: =+D23 -> 6198 | F20: =+D23 -> 6198 | G20: =+F23 -> 17831 | H20: =+G23 -> 16004 | I20: =+H23 -> 20339.373 | J20: =+I23 -> 24875.795
A21: Utilidad del año | B21: 8181 | C21: =ER!C19 -> 6185 | D21: =ER!D19 -> 14248 | E21: =ER!E19 -> 20350 | F21: =ER!F19 -> 23970 | G21: =ER!G19 -> 22147 | H21: =ER!H19 -> 25323.442 | I21: =ER!I19 -> 26497.79 | J21: =ER!J19 -> 27939.59
A22: Dividendos | B22: =B20+B21-B23 -> 6412 | C22: =C20+C21-C23 -> 10448 | D22: =D20+D21-D23 -> 13207 | E22: =E20+E21-E23 -> 12421 | F22: =F20+F21-F23 -> 12337 | G22: =G20+G21-G23 -> 23974 | H22: =+H21*Supuestos!$G$51 -> 20988.069 | I22: =+I21*Supuestos!$G$51 -> 21961.369 | J22: =+J21*Supuestos!$G$51 -> 23156.332
A23: Saldo Final | B23: =ESF!B46 -> 9420 | C23: =ESF!C46 -> 5157 | D23: =ESF!D46 -> 6198 | E23: =ESF!E46 -> 14127 | F23: =ESF!F46 -> 17831 | G23: =ESF!G46 -> 16004 | H23: =H20+H21-H22 -> 20339.373 | I23: =I20+I21-I22 -> 24875.795 | J23: =J20+J21-J22 -> 29659.053
A25: Ratio Pago de Dividendos | B25: =B22/B21 -> 0.78376727 | C25: =C22/C21 -> 1.6892482 | D25: =D22/D21 -> 0.92693711 | E25: =E22/E21 -> 0.61036855 | F25: =F22/F21 -> 0.51468502 | G25: =G22/G21 -> 1.0824942 | H25: =H22/H21 -> 0.8288 | I25: =I22/I21 -> 0.8288 | J25: =J22/J21 -> 0.8288
B28: 2019-2024
A29: UDI | B29: =+SUM(B21:G21) -> 95081
A30: Pago Dividendos | B30: =+SUM(B22:G22) -> 78799
A31: Ratio Pago de Dividendos | B31: =B30/B29 -> 0.82875653

Sheet Flujo de Efectivo
C4: 2025 | D4: 2026 | E4: 2027
B5: Ventas | C5: =+ER!H6 -> 470950.02 | D5: =+ER!I6 -> 493161.32 | E5: =+ER!J6 -> 519243.42
B6: - Variación CxC | C6: ='Fuentes Usos'!B9 -> -1914.9465 | D6: ='Fuentes Usos'!C9 -> -923.16414 | E6: ='Fuentes Usos'!D9 -> -2409.5485
B7: Ventas Cobradas | C7: =+SUM(C5:C6) -> 469035.07 | D7: =+SUM(D5:D6) -> 492238.15 | E7: =+SUM(E5:E6) -> 516833.87
C9: 2025 | D9: 2026 | E9: 2027
B10: Compras | C10: ='Fondo Maniobra'!H35 -> 417044.7 | D10: ='Fondo Maniobra'!I35 -> 431575.11 | E10: ='Fondo Maniobra'!J35 -> 460200.3
B11: -Variación CxP | C11: =-'Fuentes Usos'!B29 -> 4220.1472 | D11: =-'Fuentes Usos'!C29 -> -14639.111 | E11: =-'Fuentes Usos'!D29 -> 389.84167
B12: -Variación CxP | C12: =-'Fuentes Usos'!B30 -> 4623.95 | D12: =-'Fuentes Usos'!C30 -> -2842.5118 | E12: =-'Fuentes Usos'!D30 -> 75.696507
B13: Gastos pagados por anticipado | C13: =-+'Fuentes Usos'!B14 -> 0 | D13: =-+'Fuentes Usos'!C14 -> 0 | E13: =-+'Fuentes Usos'!D14 -> 0
B14: Depreciación | C14: =-IME!H21 -> -1480.8176 | D14: =-IME!I21 -> -1657.7111 | E14: =-IME!J21 -> -1833.3876
B15: Diferencias de Cambio neto | C15: =-ER!H16 -> 176 | D15: =-ER!I16 -> 176 | E15: =-ER!J16 -> 176
B16: Compras Pagadas | C16: =+SUM(C10:C15) -> 424583.98 | D16: =+SUM(D10:D15) -> 412611.78 | E16: =+SUM(E10:E15) -> 459008.45
C18: 2025 | D18: 2026 | E18: 2027
B19: Gastos de Ventas y Distribución | C19: =-ER!H9 -> 10476.034 | D19: =-ER!I9 -> 10931.903 | E19: =-ER!J9 -> 11468.102
B20: Depreciación | C20: =-IME!H22-IME!H36 -> -904.04559 | D20: =-IME!I22-IME!I36 -> -910.14332 | E20: =-IME!J22-IME!J36 -> -916.1991
B21: Gastos de Ventas y Distribución | C21: =+SUM(C19:C20) -> 9571.9888 | D21: =+SUM(D19:D20) -> 10021.76 | E21: =+SUM(E19:E20) -> 10551.902
C23: 2025 | D23: 2026 | E23: 2027
B24: Gastos de Administración | C24: =-ER!H10 -> 15928.767 | D24: =-ER!I10 -> 16576.895 | E24: =-ER!J10 -> 17337.078
B25: Depreciación | C25: =-IME!H23-IME!H35 -> -2066.0975 | D25: =-IME!I23-IME!I35 -> -2080.444 | E25: =-IME!J23-IME!J35 -> -2094.6917
B26: Gastos de Administración | C26: =+SUM(C24:C25) -> 13862.669 | D26: =+SUM(D24:D25) -> 14496.451 | E26: =+SUM(E24:E25) -> 15242.386
B29: METODO DIRECTO | G29: METODO INDIRECTO
C30: 2025 | D30: 2026 | E30: 2027 | H30: 2025 | I30: 2026 | J30: 2027
B31: Ingresos | C31: =+C7 -> 469035.07 | D31: =+D7 -> 492238.15 | E31: =+E7 -> 516833.87 | G31: Ganancia (Pérdida) por actividades de operación | H31: =ER!H13 -> 34667.069 | I31: =ER!I13 -> 36343.198 | J31: =ER!J13 -> 38304.824
B32: (*) Compras | C32: =-C16 -> -424583.98 | D32: =-D16 -> -412611.78 | E32: =-E16 -> -459008.45 | G32: Diferencias de Cambio neto | H32: =ER!H16 -> -176 | I32: =ER!I16 -> -176 | J32: =ER!J16 -> -176
B33: Gastos de Ventas y Distribución | C33: =-C21 -> -9571.9888 | D33: =-D21 -> -10021.76 | E33: =-E21 -> -10551.902 | G33: Ingreso (Gasto) por Impuesto | H33: =ER!H18 -> -10606.527 | I33: =ER!I18 -> -11098.394 | J33: =ER!J18 -> -11702.28
B34: Gastos de Administración | C34: =-C26 -> -13862.669 | D34: =-D26 -> -14496.451 | E34: =-E26 -> -15242.386 | G34: +Depreciacion | H34: =+IME!H14+IME!H33 -> 4450.9607 | I34: =+IME!I14+IME!I33 -> 4648.2985 | J34: =+IME!J14+IME!J33 -> 4844.2784
B35: Otros Ingresos Operativos | C35: =+ER!H11 -> 2169 | D35: =+ER!I11 -> 2169 | E35: =+ER!J11 -> 2169 | G35: -Variación CxC | H35: =+'Fuentes Usos'!B9 -> -1914.9465 | I35: =+'Fuentes Usos'!C9 -> -923.16414 | J35: =+'Fuentes Usos'!D9 -> -2409.5485
B36: Otros Gastos Operativos | C36: =+ER!H12 -> -42.385501 | D36: =+ER!I12 -> -44.384518 | E36: =+ER!J12 -> -46.731907 | G36: -Variación Inventarios | H36: =+'Fuentes Usos'!B12 -> -5039.9361 | I36: =+'Fuentes Usos'!C12 -> -141.17729 | J36: =+'Fuentes Usos'!D12 -> -5944.6212
B37: IR | C37: =+ER!H18 -> -10606.527 | D37: =+ER!I18 -> -11098.394 | E37: =+ER!J18 -> -11702.28 | G37: +Variación CxP | H37: =+'Fuentes Usos'!B29+'Fuentes Usos'!B30 -> -8844.0972 | I37: =+'Fuentes Usos'!C29+'Fuentes Usos'!C30 -> 17481.622 | J37: =+'Fuentes Usos'!D29+'Fuentes Usos'!D30 -> -465.53818
B38: FC efectivo por actividades de operación | C38: =+SUM(C31:C37) -> 12536.523 | D38: =+SUM(D31:D37) -> 46134.384 | E38: =+SUM(E31:E37) -> 22451.115 | G38: FC efectivo por actividades de operación | H38: =+SUM(H31:H37) -> 12536.523 | I38: =+SUM(I31:I37) -> 46134.384 | J38: =+SUM(J31:J37) -> 22451.115
B40: Deuda | C40: =+'Fuentes Usos'!B28+'Fuentes Usos'!B36+'Fuentes Usos'!B38 -> 0 | D40: =+'Fuentes Usos'!C28+'Fuentes Usos'!C36+'Fuentes Usos'!C38 -> 0 | E40: =+'Fuentes Usos'!D28+'Fuentes Usos'!D36+'Fuentes Usos'!D38 -> 0
B41: Gastos Financieros | C41: =+ER!H15 -> -1623.4589 | D41: =+ER!I15 -> -1700.0257 | E41: =+ER!J15 -> -1789.9359
B42: Ingresos Financieros | C42: =+ER!H14 -> 3062.3591 | D42: =+ER!I14 -> 3129.0116 | E42: =+ER!J14 -> 3302.981 | G42: (*) Incluye diferencias de cambio neto
B43: Pago Arrendamientos | C43: ='Fuentes Usos'!B33+'Fuentes Usos'!B37 -> -2073.4396 | D43: ='Fuentes Usos'!C33+'Fuentes Usos'!C37 -> 550.84025 | E43: ='Fuentes Usos'!D33+'Fuentes Usos'!D37 -> 646.83606
B44: Cuentas por Cobrar a Entidades Relacionadas | C44: =+'Fuentes Usos'!B10 -> 56056 | D44: =+'Fuentes Usos'!C10 -> 0 | E44: =+'Fuentes Usos'!D10 -> 0
B45: Otras Cuentas por Cobrar | C45: =+'Fuentes Usos'!B11 -> 2539.7296 | D45: =+'Fuentes Usos'!C11 -> -590.82059 | E45: =+'Fuentes Usos'!D11 -> -693.78384
B46: Activos por Impuestos Diferidos | C46: =+'Fuentes Usos'!B21 -> 773 | D46: =+'Fuentes Usos'!C21 -> 0 | E46: =+'Fuentes Usos'!D21 -> 0
B47: Otras cuentas por Pagar | C47: =+'Fuentes Usos'!B32 -> 0 | D47: =+'Fuentes Usos'!C32 -> 0 | E47: =+'Fuentes Usos'!D32 -> 0
B48: Pago de dividendos | C48: =-'Cambios Patrimonio'!H22 -> -20988.069 | D48: =-'Cambios Patrimonio'!I22 -> -21961.369 | E48: =-'Cambios Patrimonio'!J22 -> -23156.332
B49: Reserva Legal | C49: =+'Fuentes Usos'!B45 -> -0.4 | D49: =+'Fuentes Usos'!C45 -> 0 | E49: =+'Fuentes Usos'!D45 -> 0
...

Sheet Ventas
B4: CUENTA | C4: 2019 | D4: 2020 | E4: 2021 | F4: 2022 | G4: 2023 | H4: 2024 | I4: 2025 | J4: 2026 | K4: 2027 | N4: 2024-2019 | O4: 2024-2022
B5: Ventas Nacionales | C5: 152725 | D5: 114909 | E5: 181168 | F5: 191314 | G5: 183404 | H5: 195487 | I5: =+H5*(1+Supuestos!$C5) -> 197598.26 | J5: =+I5*(1+Supuestos!$C5) -> 199732.32 | K5: =+J5*(1+Supuestos!$C5) -> 201889.43 | M5: Ventas Nacionales | N5: =+POWER(H5/C5,1/5)-1 -> 0.050610047 | O5: =+POWER(H5/F5,1/2)-1 -> 0.010847322
B6: Ventas Exterior | C6: 26659 | D6: 46258 | E6: 101372 | F6: 96925 | G6: 72237 | H6: 82734 | I6: =+H6*(1+Supuestos!$C6) -> 76437.943 | J6: =+I6*(1+Supuestos!$C6) -> 70621.015 | K6: =+J6*(1+Supuestos!$C6) -> 65246.756 | M6: Ventas Exterior | N6: =+POWER(H6/C6,1/5)-1 -> 0.25420357 | O6: =+POWER(H6/F6,1/2)-1 -> -0.076101832
B7: Ventas a partes relacionadas | C7: 20235 | D7: 26154 | E7: 47671 | F7: 135919 | G7: 145020 | H7: 174029 | I7: =+H7*(1+Supuestos!$C7) -> 196913.81 | J7: =+I7*(1+Supuestos!$C7) -> 222807.98 | K7: =+J7*(1+Supuestos!$C7) -> 252107.23 | M7: Ventas a partes relacionadas | N7: =+POWER(H7/C7,1/5)-1 -> 0.53781355 | O7: =+POWER(H7/F7,1/2)-1 -> 0.13154213
B8: Ingresos de actividades ordinarias | C8: =+SUM(C5:C7) -> 199619 | D8: =+SUM(D5:D7) -> 187321 | E8: =+SUM(E5:E7) -> 330211 | F8: =+SUM(F5:F7) -> 424158 | G8: =+SUM(G5:G7) -> 400661 | H8: =+SUM(H5:H7) -> 452250 | I8: =+SUM(I5:I7) -> 470950.02 | J8: =+SUM(J5:J7) -> 493161.32 | K8: =+SUM(K5:K7) -> 519243.42 | M8: Ingresos de actividades ordinarias | N8: =+POWER(H8/C8,1/5)-1 -> 0.1777018 | O8: =+POWER(H8/F8,1/2)-1 -> 0.032584155
B10: Ventas Nacionales | D10: =D5/C5-1 -> -0.24760845 | E10: =E5/D5-1 -> 0.5766215 | F10: =F5/E5-1 -> 0.056003268 | G10: =G5/F5-1 -> -0.041345641 | H10: =H5/G5-1 -> 0.065881878
B11: Ventas Exterior | D11: =D6/C6-1 -> 0.73517386 | E11: =E6/D6-1 -> 1.191448 | F11: =F6/E6-1 -> -0.043868129 | G11: =G6/F6-1 -> -0.25471241 | H11: =H6/G6-1 -> 0.14531334
B12: Ventas a partes relacionadas | D12: =D7/C7-1 -> 0.29251297 | E12: =E7/D7-1 -> 0.82270398 | F12: =F7/E7-1 -> 1.8511884 | G12: =G7/F7-1 -> 0.066958998 | H12: =H7/G7-1 -> 0.20003448
B13: Ingresos de actividades ordinarias | D13: =D8/C8-1 -> -0.061607362 | E13: =E8/D8-1 -> 0.76280823 | F13: =F8/E8-1 -> 0.28450597 | G13: =G8/F8-1 -> -0.05539681 | H13: =H8/G8-1 -> 0.12875972

Sheet Costo de Ventas
B4: CUENTA | C4: 2019 | D4: 2020 | E4: 2021 | F4: 2022 | G4: 2023 | H4: 2024 | I4: 2025 | J4: 2026 | K4: 2027
B5: =+ER!A6 -> Ingresos de actividades ordinarias | C5: =+ER!B6 -> 199619 | D5: =+ER!C6 -> 187321 | E5: =+ER!D6 -> 330211 | F5: =+ER!E6 -> 424158 | G5: =+ER!F6 -> 400661 | H5: =+ER!G6 -> 452250 | I5: =+ER!H6 -> 470950.02 | ... K5: =+ER!J6 -> 519243.42
B7: CUENTA | C7: 2019 | D7: 2020 | E7: 2021 | F7: 2022 | G7: 2023 | H7: 2024 | I7: 2025 | J7: 2026 | K7: 2027
B8: =+ER!A7 -> Costo de Ventas | C8: =-ER!B7 -> 166246 | D8: =-ER!C7 -> 161990 | E8: =-ER!D7 -> 290126 | F8: =-ER!E7 -> 373656 | G8: =-ER!F7 -> 355059 | H8: =-ER!G7 -> 405000 | I8: =+I11+I15 -> 412004.76 | J8: =+J11+J15 -> 431433.94 | K8: =+K11+K15 -> 454255.68
C9: =+C8/C5 -> 0.83281652 | D9: =+D8/D5 -> 0.86477224 | E9: =+E8/E5 -> 0.87860792 | F9: =+F8/F5 -> 0.88093588 | G9: =+G8/G5 -> 0.88618308 | H9: =+H8/H5 -> 0.89552239
B10: CUENTA | C10: 2019 | D10: 2020 | E10: 2021 | F10: 2022 | G10: 2023 | H10: 2024 | I10: 2025 | J10: 2026 | K10: 2027
B11: Gasto de Personal | C11: =+'Gasto de Personal'!B20 -> 9502 | D11: =+'Gasto de Personal'!C20 -> 6800 | E11: =+'Gasto de Personal'!D20 -> 8184 | F11: =+'Gasto de Personal'!E20 -> 9878 | G11: =+'Gasto de Personal'!F20 -> 9835 | H11: =+'Gasto de Personal'!G20 -> 10108 | I11: =+'Gasto de Personal'!H20 -> 11085.012 | J11: =+'Gasto de Personal'!I20 -> 11605.707 | K11: =+'Gasto de Personal'!J20 -> 12223.761
C12: =+C11/C5 -> 0.047600679 | D12: =+D11/D5 -> 0.036301322 | E12: =+E11/E5 -> 0.024784153 | F12: =+F11/F5 -> 0.023288492 | G12: =+G11/G5 -> 0.024546936 | H12: =+H11/H5 -> 0.02235047 | I12: =+I11/I5 -> 0.023537555 | J12: =+J11/J5 -> 0.023533288 | K12: =+K11/K5 -> 0.023541484
B14: CUENTA | C14: 2019 | D14: 2020 | E14: 2021 | F14: 2022 | G14: 2023 | H14: 2024 | I14: 2025 | J14: 2026 | K14: 2027
B15: Costo Ventas Sin Gasto de Personal | C15: =+C8-C11 -> 156744 | D15: =+D8-D11 -> 155190 | E15: =+E8-E11 -> 281942 | F15: =+F8-F11 -> 363778 | G15: =+G8-G11 -> 345224 | H15: =+H8-H11 -> 394892 | I15: =+I5*Supuestos!$C$10 -> 400919.75 | J15: =+J5*Supuestos!$C$10 -> 419828.23 | K15: =+K5*Supuestos!$C$10 -> 442031.92
C16: =+C15/C5 -> 0.78521584 | D16: =+D15/D5 -> 0.82847091 | E16: =+E15/E5 -> 0.85382377 | F16: =+F15/F5 -> 0.85764739 | G16: =+G15/G5 -> 0.86163615 | H16: =+H15/H5 -> 0.87317192

Sheet Gasto de Personal
A4: CUENTA | B4: 2019 | C4: 2020 | D4: 2021 | E4: 2022 | F4: 2023 | G4: 2024 | H4: 2025 | I4: 2026 | J4: 2027
A5: Ventas | B5: =+ER!B6 -> 199619 | C5: =+ER!C6 -> 187321 | D5: =+ER!D6 -> 330211 | E5: =+ER!E6 -> 424158 | F5: =+ER!F6 -> 400661 | G5: =+ER!G6 -> 452250 | H5: =+ER!H6 -> 470950.02 | I5: =+ER!I6 -> 493161.32 | J5: =+ER!J6 -> 519243.42
A7: CUENTA | B7: 2019 | C7: 2020 | D7: 2021 | E7: 2022 | F7: 2023 | G7: 2024 | H7: 2025 | I7: 2026 | J7: 2027
A8: Remuneraciones | B8: 6557 | C8: 5223 | D8: 5213 | E8: 6194 | F8: 6248 | G8: 6314 | H8: =+H5*Supuestos!$C$14 -> 6593.3002 | I8: =+I5*Supuestos!$C$14 -> 6904.2584 | J8: =+J5*Supuestos!$C$14 -> 7269.4078
A9: Participación a los trabajadores | B9: 2176 | C9: 1483 | D9: 2757 | E9: 3471 | F9: 3110 | G9: 3191 | H9: =-'IR PT'!H18 -> 4157.0209 | I9: =-'IR PT'!I18 -> 4349.7984 | J9: =-'IR PT'!J18 -> 4586.4798
A10: Gratificaciones | B10: 1466 | C10: 1010 | D10: 1117 | E10: 1246 | F10: 1363 | G10: 1375 | H10: =+H$8*Supuestos!$C16 -> 1436.0208 | I10: =+I$8*Supuestos!$C16 -> 1503.7475 | J10: =+J$8*Supuestos!$C16 -> 1583.277
A11: CTS | B11: 795 | C11: 661 | D11: 624 | E11: 680 | F11: 787 | G11: 761 | H11: =+H$8*Supuestos!$C17 -> 794.49268 | I11: =+I$8*Supuestos!$C17 -> 831.96314 | J11: =+J$8*Supuestos!$C17 -> 875.96364
A12: Contribuciones sociales | B12: 680 | C12: 599 | D12: 557 | E12: 554 | F12: 607 | G12: 593 | H12: =+H$8*Supuestos!$C18 -> 619.11089 | I12: =+I$8*Supuestos!$C18 -> 648.30987 | J12: =+J$8*Supuestos!$C18 -> 682.59739
A13: Vacaciones | B13: 702 | C13: 564 | D13: 504 | E13: 618 | F13: 594 | G13: 683 | H13: =+H$8*Supuestos!$C19 -> 713.39508 | I13: =+I$8*Supuestos!$C19 -> 747.04076 | J13: =+J$8*Supuestos!$C19 -> 786.54993
A14: Otros | B14: 3205 | C14: 2860 | D14: 2003 | E14: 2561 | F14: 2702 | G14: 2833 | H14: =+H$8*Supuestos!$C20 -> 2958.4138 | I14: =+I$8*Supuestos!$C20 -> 3097.9408 | J14: =+J$8*Supuestos!$C20 -> 3261.7833
B15: =+SUM(B8:B14) -> 15581 | C15: =+SUM(C8:C14) -> 12400 | D15: =+SUM(D8:D14) -> 12775 | E15: =+SUM(E8:E14) -> 15324 | F15: =+SUM(F8:F14) -> 15411 | G15: =+SUM(G8:G14) -> 15750 | H15: =+SUM(H8:H14) -> 17271.754 | I15: =+SUM(I8:I14) -> 18083.059 | J15: =+SUM(J8:J14) -> 19046.059
B17: =+B8/B5 -> 0.032847575 | C17: =+C8/C5 -> 0.027882619 | D17: =+D8/D5 -> 0.015786876 | E17: =+E8/E5 -> 0.014603049 | F17: =+F8/F5 -> 0.015594231 | G17: =+G8/G5 -> 0.013961305
A18: Asignación
A19: CUENTA | B19: 2019 | C19: 2020 | D19: 2021 | E19: 2022 | F19: 2023 | G19: 2024 | H19: 2025 | I19: 2026 | J19: 2027
A20: Costo de Ventas | B20: 9502 | C20: 6800 | D20: 8184 | E20: 9878 | F20: 9835 | G20: 10108 | H20: =+H15*Supuestos!$C$23 -> 11085.012 | I20: =+I15*Supuestos!$C$23 -> 11605.707 | J20: =+J15*Supuestos!$C$23 -> 12223.761
A21: Gasto de Ventas | B21: 2780 | C21: 2611 | D21: 2317 | E21: 2885 | F21: 3047 | G21: 3040 | H21: =+H15*Supuestos!$C$24 -> 3333.4486 | I21: =+I15*Supuestos!$C$24 -> 3490.0303 | J21: =+J15*Supuestos!$C$24 -> 3675.8894
A22: Gasto de Administración | B22: 3299 | C22: 2989 | D22: 2274 | E22: 2561 | F22: 2529 | G22: 2602 | H22: =+H15*Supuestos!$C$25 -> 2853.2938 | I22: =+I15*Supuestos!$C$25 -> 2987.3213 | J22: =+J15*Supuestos!$C$25 -> 3146.4089
B23: =+SUM(B20:B22) -> 15581 | C23: =+SUM(C20:C22) -> 12400 | D23: =+SUM(D20:D22) -> 12775 | E23: =+SUM(E20:E22) -> 15324 | F23: =+SUM(F20:F22) -> 15411 | G23: =+SUM(G20:G22) -> 15750 | H23: =+SUM(H20:H22) -> 17271.754 | I23: =+SUM(I20:I22) -> 18083.059 | J23: =+SUM(J20:J22) -> 19046.059
A26: Costo de Ventas | B26: =+B20/B$23 -> 0.60984532 | C26: =+C20/C$23 -> 0.5483871 | D26: =+D20/D$23 -> 0.64062622 | E26: =+E20/E$23 -> 0.64460976 | F26: =+F20/F$23 -> 0.63818052 | G26: =+G20/G$23 -> 0.64177778
A27: Gasto de Ventas | B27: =+B21/B$23 -> 0.17842244 | C27: =+C21/C$23 -> 0.21056452 | D27: =+D21/D$23 -> 0.18136986 | E27: =+E21/E$23 -> 0.18826677 | F27: =+F21/F$23 -> 0.19771592 | G27: =+G21/G$23 -> 0.19301587
A28: Gasto de Administración | B28: =+B22/B$23 -> 0.21173224 | C28: =+C22/C$23 -> 0.24104839 | D28: =+D22/D$23 -> 0.17800391 | E28: =+E22/E$23 -> 0.16712347 | F28: =+F22/F$23 -> 0.16410356 | G28: =+G22/G$23 -> 0.16520635
A31: Remuneraciones | B31: =+B8/B$8 -> 1 | C31: =+C8/C$8 -> 1 | D31: =+D8/D$8 -> 1 | E31: =+E8/E$8 -> 1 | F31: =+F8/F$8 -> 1 | G31: =+G8/G$8 -> 1
A33: Gratificaciones | B33: =+B10/B$8 -> 0.22357786 | C33: =+C10/C$8 -> 0.19337545 | D33: =+D10/D$8 -> 0.21427201 | E33: =+E10/E$8 -> 0.20116242 | F33: =+F10/F$8 -> 0.21814981 | G33: =+G10/G$8 -> 0.21777003 | J33: Gratificaciones | K33: =2/12 -> 0.16666667
A34: CTS | B34: =+B11/B$8 -> 0.12124447 | C34: =+C11/C$8 -> 0.12655562 | D34: =+D11/D$8 -> 0.11970075 | E34: =+E11/E$8 -> 0.10978366 | F34: =+F11/F$8 -> 0.12596031 | G34: =+G11/G$8 -> 0.12052582 | J34: CTS | K34: =1/12 -> 0.083333333
A35: Contribuciones sociales | B35: =+B12/B$8 -> 0.10370596 | C35: =+C12/C$8 -> 0.11468505 | D35: =+D12/D$8 -> 0.10684826 | E35: =+E12/E$8 -> 0.089441395 | F35: =+F12/F$8 -> 0.097151088 | G35: =+G12/G$8 -> 0.093918277 | J35: Essalud | K35: 0.09
A36: Vacaciones | B36: =+B13/B$8 -> 0.10706116 | C36: =+C13/C$8 -> 0.10798392 | D36: =+D13/D$8 -> 0.096681373 | E36: =+E13/E$8 -> 0.099773975 | F36: =+F13/F$8 -> 0.095070423 | G36: =+G13/G$8 -> 0.10817232 | J36: Vacaciones | K36: =1/12 -> 0.083333333
A37: Otros | B37: =+B14/B$8 -> 0.48879061 | C37: =+C14/C$8 -> 0.54757802 | D37: =+D14/D$8 -> 0.38423173 | E37: =+E14/E$8 -> 0.41346464 | F37: =+F14/F$8 -> 0.43245839 | G37: =+G14/G$8 -> 0.44868546 | K37: =+SUM(K33:K36) -> 0.42333333
A39: CUENTA | B39: 2019 | C39: 2020 | D39: 2021 | E39: 2022 | F39: 2023 | G39: 2024 | H39: 2025 | I39: 2026 | J39: 2027
A40: Total Sin Partic Trabajadores | B40: =+SUM(B8,B10:B14) -> 13405 | C40: =+SUM(C8,C10:C14) -> 10917 | D40: =+SUM(D8,D10:D14) -> 10018 | E40: =+SUM(E8,E10:E14) -> 11853 | F40: =+SUM(F8,F10:F14) -> 12301 | G40: =+SUM(G8,G10:G14) -> 12559 | H40: =+SUM(H8,H10:H14) -> 13114.733 | I40: =+SUM(I8,I10:I14) -> 13733.26 | J40: =+SUM(J8,J10:J14) -> 14459.579

Sheet Gasto de Ventas
A4: CUENTA | B4: 2019 | C4: 2020 | D4: 2021 | E4: 2022 | F4: 2023 | G4: 2024 | H4: 2025 | I4: 2026 | J4: 2027
A5: Ingresos de actividades ordinarias | B5: =+ER!B6 -> 199619 | C5: =+ER!C6 -> 187321 | D5: =+ER!D6 -> 330211 | E5: =+ER!E6 -> 424158 | F5: =+ER!F6 -> 400661 | G5: =+ER!G6 -> 452250 | H5: =+ER!H6 -> 470950.02 | I5: =+ER!I6 -> 493161.32 | J5: =+ER!J6 -> 519243.42
A7: CUENTA | B7: 2019 | C7: 2020 | D7: 2021 | E7: 2022 | F7: 2023 | G7: 2024 | H7: 2025 | I7: 2026 | J7: 2027
A8: Servicios Recibidos | B8: 2767 | C8: 2113 | D8: 3554 | E8: 5718 | F8: 3820 | G8: 4084 | H8: =+H5*Supuestos!$C$29 -> 5227.5452 | I8: =+I5*Supuestos!$C$29 -> 5474.0906 | J8: =+J5*Supuestos!$C$29 -> 5763.6019
A9: Gastos de Personal | B9: 2780 | C9: 2611 | D9: 2317 | E9: 2885 | F9: 3047 | G9: 3040 | H9: =+'Gasto de Personal'!H21 -> 3333.4486 | I9: =+'Gasto de Personal'!I21 -> 3490.0303 | J9: =+'Gasto de Personal'!J21 -> 3675.8894
A10: Cargas diversas de gestión | B10: 680 | C10: 308 | D10: 1178 | E10: 574 | F10: 1086 | G10: 449 | H10: =+H5*Supuestos!$C$30 -> 988.99503 | I10: =+I5*Supuestos!$C$30 -> 1035.6388 | J10: =+J5*Supuestos!$C$30 -> 1090.4112
A11: Depreciación por derecho de uso | B11: 939 | C11: 939 | D11: 945 | E11: 962 | F11: 845 | G11: 853 | H11: =IME!H36 -> 853 | I11: =IME!I36 -> 853 | J11: =IME!J36 -> 853
A12: Depreciación por IME | B12: 71 | C12: 40 | D12: 40 | E12: 61 | F12: 84 | G12: 105 | H12: =+IME!H22 -> 51.045586 | I12: =+IME!I22 -> 57.143323 | J12: =+IME!J22 -> 63.199103
A13: Tributos | B13: 28 | C13: 28 | D13: 25 | E13: 27 | F13: 21 | G13: 22 | H13: =+G13 -> 22 | I13: =+H13 -> 22 | J13: =+I13 -> 22
A14: Amortización Intangibles | B14: 3 | C14: 2 | D14: 2 | E14: 0 | F14: 0 | G14: 0 | H14: =+G14 -> 0 | I14: =+H14 -> 0 | J14: =+I14 -> 0
B15: =+SUM(B8:B14) -> 7268 | C15: =+SUM(C8:C14) -> 6041 | D15: =+SUM(D8:D14) -> 8061 | E15: =+SUM(E8:E14) -> 10227 | F15: =+SUM(F8:F14) -> 8903 | G15: =+SUM(G8:G14) -> 8553 | H15: =+SUM(H8:H14) -> 10476.034 | I15: =+SUM(I8:I14) -> 10931.903 | J15: =+SUM(J8:J14) -> 11468.102
A17: CUENTA | B17: 2019 | C17: 2020 | D17: 2021 | E17: 2022 | F17: 2023 | G17: 2024 | H17: 2025 | I17: 2026 | J17: 2027
A18: Total Sin Gasto de Personal | B18: =+SUM(B8,B10:B14) -> 4488 | C18: =+SUM(C8,C10:C14) -> 3430 | D18: =+SUM(D8,D10:D14) -> 5744 | E18: =+SUM(E8,E10:E14) -> 7342 | F18: =+SUM(F8,F10:F14) -> 5856 | G18: =+SUM(G8,G10:G14) -> 5513 | H18: =+SUM(H8,H10:H14) -> 7142.5858 | I18: =+SUM(I8,I10:I14) -> 7441.8727 | J18: =+SUM(J8,J10:J14) -> 7792.2122

Sheet Gasto de Administración
A4: CUENTA | B4: 2019 | C4: 2020 | D4: 2021 | E4: 2022 | F4: 2023 | G4: 2024 | H4: 2025 | I4: 2026 | J4: 2027
A5: Ingresos de actividades ordinarias | B5: =+ER!B6 -> 199619 | C5: =+ER!C6 -> 187321 | D5: =+ER!D6 -> 330211 | E5: =+ER!E6 -> 424158 | F5: =+ER!F6 -> 400661 | G5: =+ER!G6 -> 452250 | H5: =+ER!H6 -> 470950.02 | I5: =+ER!I6 -> 493161.32 | J5: =+ER!J6 -> 519243.42
A8: CUENTA | B8: 2019 | C8: 2020 | D8: 2021 | E8: 2022 | F8: 2023 | G8: 2024 | H8: 2025 | I8: 2026 | J8: 2027
A9: Servicios Recibidos | B9: 5730 | C9: 4519 | D9: 6703 | E9: 7142 | F9: 7354 | G9: 7023 | H9: =+H5*Supuestos!$C$33 -> 9089.3353 | I9: =+I5*Supuestos!$C$33 -> 9518.0134 | J9: =+J5*Supuestos!$C$33 -> 10021.398
A10: Gastos de Personal | B10: 3299 | C10: 2989 | D10: 2274 | E10: 2561 | F10: 2529 | G10: 2602 | H10: =+'Gasto de Personal'!H22 -> 2853.2938 | I10: =+'Gasto de Personal'!I22 -> 2987.3213 | J10: =+'Gasto de Personal'!J22 -> 3146.4089
A11: Depreciación por derecho de uso | B11: 0 | C11: 1684 | D11: 2020 | E11: 1810 | F11: 1946 | G11: 1946 | H11: =IME!H35 -> 1946 | I11: =IME!I35 -> 1946 | J11: =IME!J35 -> 1946
A12: Cargas Diversas de gestión | B12: 505 | C12: 368 | D12: 632 | E12: 1255 | F12: 2430 | G12: 1138 | H12: =+H5*Supuestos!$C$34 -> 1507.0401 | I12: =+I5*Supuestos!$C$34 -> 1578.1162 | J12: =+J5*Supuestos!$C$34 -> 1661.5789
A13: Tributos | B13: 195 | C13: 134 | D13: 139 | E13: 212 | F13: 249 | G13: 230 | H13: =+G13 -> 230 | I13: =+H13 -> 230 | J13: =+I13 -> 230
A14: Depreciación por IME | B14: 66 | C14: 48 | D14: 55 | E14: 84 | F14: 148 | G14: 247 | H14: =+IME!H23 -> 120.09754 | I14: =+IME!I23 -> 134.444 | J14: =+IME!J23 -> 148.69174
A15: Amortización Intangibles | B15: 21 | C15: 19 | D15: 6 | E15: 4 | F15: 4 | G15: 35 | H15: =+G15 -> 35 | I15: =+H15 -> 35 | J15: =+I15 -> 35
A16: Provisiones por perdida crediticia | B16: 194 | C16: -47 | D16: -12 | E16: 718 | F16: 7 | G16: 28 | H16: =+Supuestos!$C$35 -> 148 | I16: =+Supuestos!$C$35 -> 148 | J16: =+Supuestos!$C$35 -> 148
B17: =+SUM(B9:B16) -> 10010 | C17: =+SUM(C9:C16) -> 9714 | D17: =+SUM(D9:D16) -> 11817 | E17: =+SUM(E9:E16) -> 13786 | F17: =+SUM(F9:F16) -> 14667 | G17: =+SUM(G9:G16) -> 13249 | H17: =+SUM(H9:H16) -> 15928.767 | I17: =+SUM(I9:I16) -> 16576.895 | J17: =+SUM(J9:J16) -> 17337.078
A19: CUENTA | B19: 2019 | C19: 2020 | D19: 2021 | E19: 2022 | F19: 2023 | G19: 2024 | H19: 2025 | I19: 2026 | J19: 2027
A20: Total Sin Gasto de Personal | B20: =+SUM(B9,B11:B16) -> 6711 | C20: =+SUM(C9,C11:C16) -> 6725 | D20: =+SUM(D9,D11:D16) -> 9543 | E20: =+SUM(E9,E11:E16) -> 11225 | F20: =+SUM(F9,F11:F16) -> 12138 | G20: =+SUM(G9,G11:G16) -> 10647 | H20: =+SUM(H9,H11:H16) -> 13075.473 | I20: =+SUM(I9,I11:I16) -> 13589.574 | J20: =+SUM(J9,J11:J16) -> 14190.669

Sheet Ing Financieros
A4: CUENTA | B4: 2019 | C4: 2020 | D4: 2021 | E4: 2022 | F4: 2023 | G4: 2024 | H4: 2025 | I4: 2026 | J4: 2027
A5: Ingresos Financieros | B5: =+ER!B14 -> 386 | C5: =+ER!C14 -> 843 | D5: =+ER!D14 -> 2507 | E5: =+ER!E14 -> 1351 | F5: =+ER!F14 -> 4855 | G5: =+ER!G14 -> 5148 | H5: =+H11*Supuestos!$C$49 -> 3062.3591 | I5: =+I11*Supuestos!$C$49 -> 3129.0116 | J5: =+J11*Supuestos!$C$49 -> 3302.981
A8: CUENTA | B8: 2019 | C8: 2020 | D8: 2021 | E8: 2022 | F8: 2023 | G8: 2024 | H8: 2025 | I8: 2026 | J8: 2027
A9: Cuentas por Cobrar Comerciales | B9: =+ESF!B9 -> 24037 | C9: =+ESF!C9 -> 17377 | D9: =+ESF!D9 -> 28388 | E9: =+ESF!E9 -> 26997 | F9: =+ESF!F9 -> 25283 | G9: =+ESF!G9 -> 29131 | H9: =+ESF!H9 -> 31045.946 | I9: =+ESF!I9 -> 31969.111 | J9: =+ESF!J9 -> 34378.659
A10: Inversiones en subsidiarias, negocios conjuntos y asociadas | B10: =+ESF!B17 -> 2080 | C10: =+ESF!C17 -> 11016 | D10: =+ESF!D17 -> 10991 | E10: =+ESF!E17 -> 11074 | F10: =+ESF!F17 -> 11151 | G10: =+ESF!G17 -> 11369 | H10: =+ESF!H17 -> 11369 | I10: =+ESF!I17 -> 11369 | J10: =+ESF!J17 -> 11369
A11: Total | B11: =+SUM(B9:B10) -> 26117 | C11: =+SUM(C9:C10) -> 28393 | D11: =+SUM(D9:D10) -> 39379 | E11: =+SUM(E9:E10) -> 38071 | F11: =+SUM(F9:F10) -> 36434 | G11: =+SUM(G9:G10) -> 40500 | H11: =+SUM(H9:H10) -> 42414.946 | I11: =+SUM(I9:I10) -> 43338.111 | J11: =+SUM(J9:J10) -> 45747.659

Sheet Gasto Financiero
A4: CUENTA | B4: 2019 | C4: 2020 | D4: 2021 | E4: 2022 | F4: 2023 | G4: 2024 | H4: 2025 | I4: 2026 | J4: 2027
A5: Gastos Financieros | B5: =-ER!B15 -> 976 | C5: =-ER!C15 -> 1187 | D5: =-ER!D15 -> 814 | E5: =-ER!E15 -> 1449 | F5: =-ER!F15 -> 1337 | G5: =-ER!G15 -> 1106 | H5: =+H11*Supuestos!$C$50 -> 1623.4589 | I5: =+I11*Supuestos!$C$50 -> 1700.0257 | J5: =+J11*Supuestos!$C$50 -> 1789.9359
A8: CUENTA | B8: 2019 | C8: 2020 | D8: 2021 | E8: 2022 | F8: 2023 | G8: 2024 | H8: 2025 | I8: 2026 | J8: 2027
A9: Pasivos por arrendamientos | B9: =+ESF!B33 -> 875 | C9: =+ESF!C33 -> 4076 | D9: =+ESF!D33 -> 3088 | E9: =+ESF!E33 -> 2781 | F9: =+ESF!F33 -> 3019 | G9: =+ESF!G33 -> 3028 | H9: =+ESF!H33 -> 3986.234 | I9: =+ESF!I33 -> 4174.2357 | J9: =+ESF!J33 -> 4395.0009
A10: Pasivos por arrendamientos | B10: =+ESF!B37 -> 2934 | C10: =+ESF!C37 -> 6246 | D10: =+ESF!D37 -> 3237 | E10: =+ESF!E37 -> 6168 | F10: =+ESF!F37 -> 3250 | G10: =+ESF!G37 -> 10725 | H10: =+ESF!H37 -> 7693.3264 | I10: =+ESF!I37 -> 8056.1649 | J10: =+ESF!J37 -> 8482.2358
A11: Total arrendamiento | B11: =+SUM(B9:B10) -> 3809 | C11: =+SUM(C9:C10) -> 10322 | D11: =+SUM(D9:D10) -> 6325 | E11: =+SUM(E9:E10) -> 8949 | F11: =+SUM(F9:F10) -> 6269 | G11: =+SUM(G9:G10) -> 13753 | H11: =+SUM(H9:H10) -> 11679.56 | I11: =+SUM(I9:I10) -> 12230.401 | J11: =+SUM(J9:J10) -> 12877.237

Sheet Otros Gastos Op
A4: CUENTA | B4: 2019 | C4: 2020 | D4: 2021 | E4: 2022 | F4: 2023 | G4: 2024 | H4: 2025 | I4: 2026 | J4: 2027
A5: Ventas | B5: =+ER!B6 -> 199619 | C5: =+ER!C6 -> 187321 | D5: =+ER!D6 -> 330211 | E5: =+ER!E6 -> 424158 | F5: =+ER!F6 -> 400661 | G5: =+ER!G6 -> 452250 | H5: =+ER!H6 -> 470950.02 | I5: =+ER!I6 -> 493161.32 | J5: =+ER!J6 -> 519243.42
A7: CUENTA | B7: 2019 | C7: 2020 | D7: 2021 | E7: 2022 | F7: 2023 | G7: 2024 | H7: 2025 | I7: 2026 | J7: 2027
A8: =+ER!A12 -> Otros Gastos Operativos | B8: =-ER!B12 -> 11 | C8: =-ER!C12 -> 10 | D8: =-ER!D12 -> 41 | E8: =-ER!E12 -> 50 | F8: =-ER!F12 -> 36 | G8: =-ER!G12 -> 34 | H8: =+H5*Supuestos!$C$48 -> 42.385501 | I8: =+I5*Supuestos!$C$48 -> 44.384518 | J8: =+J5*Supuestos!$C$48 -> 46.731907

Sheet IR PT
A4: CUENTA | B4: 2019 | C4: 2020 | D4: 2021 | E4: 2022 | F4: 2023 | G4: 2024 | H4: 2025 | I4: 2026 | J4: 2027
A5: Ingresos de actividades ordinarias | B5: =+ER!B6 -> 199619 | C5: =+ER!C6 -> 187321 | D5: =+ER!D6 -> 330211 | E5: =+ER!E6 -> 424158 | F5: =+ER!F6 -> 400661 | G5: =+ER!G6 -> 452250 | H5: =+ER!H6 -> 470950.02 | I5: =+ER!I6 -> 493161.32 | J5: =+ER!J6 -> 519243.42
A6: Costo de Ventas | B6: =-'Costo de Ventas'!C15 -> -156744 | C6: =-'Costo de Ventas'!D15 -> -155190 | D6: =-'Costo de Ventas'!E15 -> -281942 | E6: =-'Costo de Ventas'!F15 -> -363778 | F6: =-'Costo de Ventas'!G15 -> -345224 | G6: =-'Costo de Ventas'!H15 -> -394892 | H6: =-'Costo de Ventas'!I15 -> -400919.75 | I6: =-'Costo de Ventas'!J15 -> -419828.23 | J6: =-'Costo de Ventas'!K15 -> -442031.92
A7: Ganancia (Pérdida) Bruta | B7: =+SUM(B5:B6) -> 42875 | C7: =+SUM(C5:C6) -> 32131 | D7: =+SUM(D5:D6) -> 48269 | E7: =+SUM(E5:E6) -> 60380 | F7: =+SUM(F5:F6) -> 55437 | G7: =+SUM(G5:G6) -> 57358 | H7: =+SUM(H5:H6) -> 70030.267 | I7: =+SUM(I5:I6) -> 73333.088 | J7: =+SUM(J5:J6) -> 77211.496
A8: Gastos de Ventas y Distribución | B8: =-'Gasto de Ventas'!B18 -> -4488 | C8: =-'Gasto de Ventas'!C18 -> -3430 | D8: =-'Gasto de Ventas'!D18 -> -5744 | E8: =-'Gasto de Ventas'!E18 -> -7342 | F8: =-'Gasto de Ventas'!F18 -> -5856 | G8: =-'Gasto de Ventas'!G18 -> -5513 | H8: =-'Gasto de Ventas'!H18 -> -7142.5858 | I8: =-'Gasto de Ventas'!I18 -> -7441.8727 | J8: =-'Gasto de Ventas'!J18 -> -7792.2122
A9: Gastos de Administración | B9: =-'Gasto de Administración'!B20 -> -6711 | C9: =-'Gasto de Administración'!C20 -> -6725 | D9: =-'Gasto de Administración'!D20 -> -9543 | E9: =-'Gasto de Administración'!E20 -> -11225 | F9: =-'Gasto de Administración'!F20 -> -12138 | G9: =-'Gasto de Administración'!G20 -> -10647 | H9: =-'Gasto de Administración'!H20 -> -13075.473 | I9: =-'Gasto de Administración'!I20 -> -13589.574 | J9: =-'Gasto de Administración'!J20 -> -14190.669
A10: Gasto de Personal | B10: =-'Gasto de Personal'!B40 -> -13405 | C10: =-'Gasto de Personal'!C40 -> -10917 | D10: =-'Gasto de Personal'!D40 -> -10018 | E10: =-'Gasto de Personal'!E40 -> -11853 | F10: =-'Gasto de Personal'!F40 -> -12301 | G10: =-'Gasto de Personal'!G40 -> -12559 | H10: =-'Gasto de Personal'!H40 -> -13114.733 | I10: =-'Gasto de Personal'!I40 -> -13733.26 | J10: =-'Gasto de Personal'!J40 -> -14459.579
A11: Otros Ingresos Operativos | B11: =+ER!B11 -> 1430 | C11: =+ER!C11 -> 1875 | D11: =+ER!D11 -> 1341 | E11: =+ER!E11 -> 850 | F11: =+ER!F11 -> 5634 | G11: =+ER!G11 -> 1881 | H11: =+ER!H11 -> 2169 | I11: =+ER!I11 -> 2169 | J11: =+ER!J11 -> 2169
A12: Otros Gastos Operativos | B12: =+ER!B12 -> -11 | C12: =+ER!C12 -> -10 | D12: =+ER!D12 -> -41 | E12: =+ER!E12 -> -50 | F12: =+ER!F12 -> -36 | G12: =+ER!G12 -> -34 | H12: =+ER!H12 -> -42.385501 | I12: =+ER!I12 -> -44.384518 | J12: =+ER!J12 -> -46.731907
A13: Ganancia (Pérdida) por actividades de operación | B13: =+SUM(B7:B12) -> 19690 | C13: =+SUM(C7:C12) -> 12924 | D13: =+SUM(D7:D12) -> 24264 | E13: =+SUM(E7:E12) -> 30760 | F13: =+SUM(F7:F12) -> 30740 | G13: =+SUM(G7:G12) -> 30486 | H13: =+SUM(H7:H12) -> 38824.09 | I13: =+SUM(I7:I12) -> 40692.996 | J13: =+SUM(J7:J12) -> 42891.304
A14: Ingresos Financieros | B14: =+ER!B14 -> 386 | C14: =+ER!C14 -> 843 | D14: =+ER!D14 -> 2507 | E14: =+ER!E14 -> 1351 | F14: =+ER!F14 -> 4855 | G14: =+ER!G14 -> 5148 | H14: =+ER!H14 -> 3062.3591 | I14: =+ER!I14 -> 3129.0116 | J14: =+ER!J14 -> 3302.981
A15: Gastos Financieros | B15: =+ER!B15 -> -976 | C15: =+ER!C15 -> -1187 | D15: =+ER!D15 -> -814 | E15: =+ER!E15 -> -1449 | F15: =+ER!F15 -> -1337 | G15: =+ER!G15 -> -1106 | H15: =+ER!H15 -> -1623.4589 | I15: =+ER!I15 -> -1700.0257 | J15: =+ER!J15 -> -1789.9359
A16: Diferencias de Cambio neto | B16: =+ER!B16 -> -94 | C16: =+ER!C16 -> -565 | D16: =+ER!D16 -> -1076 | E16: =+ER!E16 -> 347 | F16: =+ER!F16 -> 297 | G16: =+ER!G16 -> 37 | H16: =+ER!H16 -> -176 | I16: =+ER!I16 -> -176 | J16: =+ER!J16 -> -176
A17: Base Participación Trabajadores | B17: =+SUM(B13:B16) -> 19006 | C17: =+SUM(C13:C16) -> 12015 | D17: =+SUM(D13:D16) -> 24881 | E17: =+SUM(E13:E16) -> 31009 | F17: =+SUM(F13:F16) -> 34555 | G17: =+SUM(G13:G16) -> 34565 | H17: =+SUM(H13:H16) -> 40086.99 | I17: =+SUM(I13:I16) -> 41945.982 | J17: =+SUM(J13:J16) -> 44228.349
A18: =+'Gasto de Personal'!A9 -> Participación a los trabajadores | B18: =-'Gasto de Personal'!B9 -> -2176 | C18: =-'Gasto de Personal'!C9 -> -1483 | D18: =-'Gasto de Personal'!D9 -> -2757 | E18: =-'Gasto de Personal'!E9 -> -3471 | F18: =-'Gasto de Personal'!F9 -> -3110 | G18: =-'Gasto de Personal'!G9 -> -3191 | H18: =-H17*Supuestos!$C$54 -> -4157.0209 | I18: =-I17*Supuestos!$C$54 -> -4349.7984 | J18: =-J17*Supuestos!$C$54 -> -4586.4798
A19: Resultado antes de Impuesto a las Ganancias | B19: =+B17+B18 -> 16830 | C19: =+C17+C18 -> 10532 | D19: =+D17+D18 -> 22124 | E19: =+E17+E18 -> 27538 | F19: =+F17+F18 -> 31445 | G19: =+G17+G18 -> 31374 | H19: =+H17+H18 -> 35929.969 | I19: =+I17+I18 -> 37596.184 | J19: =+J17+J18 -> 39641.869
A20: Ingreso (Gasto) por Impuesto | B20: =ER!B18 -> -5165 | C20: =ER!C18 -> -4347 | D20: =ER!D18 -> -7876 | E20: =ER!E18 -> -7188 | F20: =ER!F18 -> -7475 | G20: =ER!G18 -> -9227 | H20: =ER!H18 -> -10606.527 | I20: =ER!I18 -> -11098.394 | J20: =ER!J18 -> -11702.28
A21: Ganancia (Pérdida) Neta del Ejercicio | B21: =+SUM(B19:B20) -> 11665 | C21: =+SUM(C19:C20) -> 6185 | D21: =+SUM(D19:D20) -> 14248 | E21: =+SUM(E19:E20) -> 20350 | F21: =+SUM(F19:F20) -> 23970 | G21: =+SUM(G19:G20) -> 22147 | H21: =+SUM(H19:H20) -> 25323.442 | I21: =+SUM(I19:I20) -> 26497.79 | J21: =+SUM(J19:J20) -> 27939.59
B22: =+B21-ER!B19 -> 0 | C22: =+C21-ER!C19 -> 0 | D22: =+D21-ER!D19 -> 0 | E22: =+E21-ER!E19 -> 0 | F22: =+F21-ER!F19 -> 0 | G22: =+G21-ER!G19 -> 0
A23: Tasa Efectiva IR | B23: =-B20/B19 -> 0.30689245 | C23: =-C20/C19 -> 0.41274212 | D23: =-D20/D19 -> 0.35599349 | E23: =-E20/E19 -> 0.26102113 | F23: =-F20/F19 -> 0.23771665 | G23: =-G20/G19 -> 0.29409702 | H23: =-H20/H19 -> 0.2952 | I23: =-I20/I19 -> 0.2952 | J23: =-J20/J19 -> 0.2952
A24: Tasa Efectiva IR + PT | B24: =(-B18-B20)/B17 -> 0.38624645 | C24: =(-C18-C20)/C17 -> 0.4852268 | D24: =(-D18-D20)/D17 -> 0.42735421 | E24: =(-E18-E20)/E17 -> 0.34373891 | F24: =(-F18-F20)/F17 -> 0.30632325 | G24: =(-G18-G20)/G17 -> 0.35926515 | H24: =(-H18-H20)/H17 -> 0.36828776 | I24: =(-I18-I20)/I17 -> 0.36828776 | J24: =(-J18-J20)/J17 -> 0.36828776
B25: =+B21=ER!B19 -> TRUE | C25: =+C21=ER!C19 -> TRUE | D25: =+D21=ER!D19 -> TRUE | E25: =+E21=ER!E19 -> TRUE | F25: =+F21=ER!F19 -> TRUE | G25: =+G21=ER!G19 -> TRUE

Sheet IME
B4: 2019 | C4: 2020 | D4: 2021 | E4: 2022 | F4: 2023 | G4: 2024 | H4: 2025 | I4: 2026 | J4: 2027
A5: =+ER!A6 -> Ingresos de actividades ordinarias | B5: =+ER!B6 -> 199619 | C5: =+ER!C6 -> 187321 | D5: =+ER!D6 -> 330211 | E5: =+ER!E6 -> 424158 | F5: =+ER!F6 -> 400661 | G5: =+ER!G6 -> 452250 | H5: =+ER!H6 -> 470950.02 | ... J5: =+ER!J6 -> 519243.42
A6: Propiedades, Planta y Equipo
B7: 2019 | C7: 2020 | D7: 2021 | E7: 2022 | F7: 2023 | G7: 2024 | H7: 2025 | I7: 2026 | J7: 2027
A8: Costo Inicio | B8: 38563 | C8: =+B16 -> 37597 | D8: =+C16 -> 27160 | E8: =+D16 -> 26929 | F8: =+E16 -> 29140 | G8: =+F16 -> 29112 | H8: =+G16 -> 18499 | I8: =+H16 -> 20708.829 | J8: =+I16 -> 22903.454
A9: (-) Aporte a la subsidiria | C9: 9520
A10: (+) Transferencias desde propiedades | C10: 879
A11: (+) Adiciones | B11: 2092 | C11: 907 | D11: 2170 | E11: 4745 | F11: 2922 | G11: 3583 | H11: =H5*Supuestos!$G$21 -> 3861.7901 | I11: =I5*Supuestos!$G$21 -> 4043.9228 | J11: =J5*Supuestos!$G$21 -> 4257.796
A12: (-) Retiros | B12: 11 | C12: 29 | D12: 42 | E12: 50 | F12: 36 | G12: 29 | H12: =+Supuestos!G24 -> 0 | I12: =+Supuestos!H24 -> 0 | J12: =+Supuestos!I24 -> 0
A13: (-) Transferencias | B13: 29 | D13: 0 | E13: 13 | F13: 7 | G13: 10769
A14: (-) Depreciación historico anual | B14: 3018 | C14: 2674 | D14: 2359 | E14: 2471 | F14: 2907 | G14: 3398 | H14: =+H8*Supuestos!$C$38 -> 1651.9607 | I14: =+I8*Supuestos!$C$38 -> 1849.2985 | J14: =+J8*Supuestos!$C$38 -> 2045.2784
A15: (-) Depreciación adiciones
A16: Costo Fin | B16: =+B8+B11-B12-B13-B14-B15-B9+B10 -> 37597 | C16: =+C8+C11-C12-C13-C14-C15-C9+C10 -> 27160 | D16: =+D8+D11-D12-D13-D14-D15-D9+D10 -> 26929 | E16: =+E8+E11-E12-E13-E14-E15-E9+E10 -> 29140 | F16: =+F8+F11-F12-F13-F14-F15-F9+F10 -> 29112 | G16: =+G8+G11-G12-G13-G14-G15-G9+G10 -> 18499 | H16: =+H8+H11-H12-H13-H14-H15-H9+H10 -> 20708.829 | I16: =+I8+I11-I12-I13-I14-I15-I9+I10 -> 22903.454 | J16: =+J8+J11-J12-J13-J14-J15-J9+J10 -> 25115.971
B17: =+ESF!B19 -> 37597 | C17: =+ESF!C19 -> 27160 | D17: =+ESF!D19 -> 26929 | E17: =+ESF!E19 -> 29140 | F17: =+ESF!F19 -> 29112 | G17: =+ESF!G19 -> 18499
B18: =+B14/B8 -> 0.078261546 | C18: =+C14/C8 -> 0.071122696 | D18: =+D14/D8 -> 0.08685567 | E18: =+E14/E8 -> 0.091759813 | F18: =+F14/F8 -> 0.09975978 | G18: =+G14/G8 -> 0.11672163
B20: 2019 | C20: 2020 | D20: 2021 | E20: 2022 | F20: 2023 | G20: 2024 | H20: 2025 | I20: 2026 | J20: 2027
A21: Costo de Ventas | B21: 2881 | C21: 2586 | D21: 2264 | E21: 2326 | F21: 2675 | G21: 3046 | H21: =+H$14*Supuestos!$C41 -> 1480.8176 | I21: =+I$14*Supuestos!$C41 -> 1657.7111 | J21: =+J$14*Supuestos!$C41 -> 1833.3876
A22: Gasto de Ventas | B22: 71 | C22: 40 | D22: 40 | E22: 61 | F22: 84 | G22: 105 | H22: =+H$14*Supuestos!$C42 -> 51.045586 | I22: =+I$14*Supuestos!$C42 -> 57.143323 | J22: =+J$14*Supuestos!$C42 -> 63.199103
A23: Gasto de Administración | B23: 66 | C23: 48 | D23: 55 | E23: 84 | F23: 148 | G23: 247 | H23: =+H$14*Supuestos!$C43 -> 120.09754 | I23: =+I$14*Supuestos!$C43 -> 134.444 | J23: =+J$14*Supuestos!$C43 -> 148.69174
B24: =+SUM(B21:B23) -> 3018 | C24: =+SUM(C21:C23) -> 2674 | D24: =+SUM(D21:D23) -> 2359 | E24: =+SUM(E21:E23) -> 2471 | F24: =+SUM(F21:F23) -> 2907 | G24: =+SUM(G21:G23) -> 3398 | H24: =+SUM(H21:H23) -> 1651.9607 | I24: =+SUM(I21:I23) -> 1849.2985 | J24: =+SUM(J21:J23) -> 2045.2784
A26: Costo de Ventas | B26: =+B21/B$24 -> 0.9546057 | C26: =+C21/C$24 -> 0.9670905 | D26: =+D21/D$24 -> 0.9597287 | E26: =+E21/E$24 -> 0.9413193 | F26: =+F21/F$24 -> 0.92019264 | G26: =+G21/G$24 -> 0.89640965
A27: Gasto de Ventas | B27: =+B22/B$24 -> 0.023525514 | C27: =+C22/C$24 -> 0.014958863 | D27: =+D22/D$24 -> 0.016956337 | E27: =+E22/E$24 -> 0.024686362 | F27: =+F22/F$24 -> 0.028895769 | G27: =+G22/G$24 -> 0.03090053
A28: Gasto de Administración | B28: =+B23/B$24 -> 0.021868787 | C28: =+C23/C$24 -> 0.017950636 | D28: =+D23/D$24 -> 0.023314964 | E28: =+E23/E$24 -> 0.033994334 | F28: =+F23/F$24 -> 0.050911593 | G28: =+G23/G$24 -> 0.072689818
B30: 2019 | C30: 2020 | D30: 2021 | E30: 2022 | F30: 2023 | G30: 2024 | H30: 2025 | I30: 2026 | J30: 2027
A31: Activos por derecho de uso Inicio | B31: 4655 | C31: =B34 -> 3716 | D31: =C34 -> 8839 | E31: =D34 -> 5945 | F31: =E34 -> 8258 | G31: =F34 -> 5590 | H31: =G34 -> 13327 | I31: =H34 -> 10784.755 | J31: =I34 -> 11293.394
A32: Adiciones | B32: =B33+B34-B31 -> 0 | C32: =C33+C34-C31 -> 7746 | D32: =D33+D34-D31 -> 71 | E32: =E33+E34-E31 -> 5085 | F32: =F33+F34-F31 -> 123 | G32: =G33+G34-G31 -> 10536 | H32: =H33+H34-H31 -> 256.75536 | I32: =I33+I34-I31 -> 3307.6388 | J32: =J33+J34-J31 -> 3396.2801
A33: Depreciación Activos por derecho de uso | B33: 939 | C33: 2623 | D33: 2965 | E33: 2772 | F33: 2791 | G33: 2799 | H33: =Supuestos!$G$28 -> 2799 | I33: =Supuestos!$G$28 -> 2799 | J33: =Supuestos!$G$28 -> 2799
A34: Activos por derecho de uso Fin | B34: =+ESF!B22 -> 3716 | C34: =+ESF!C22 -> 8839 | D34: =+ESF!D22 -> 5945 | E34: =+ESF!E22 -> 8258 | F34: =+ESF!F22 -> 5590 | G34: =+ESF!G22 -> 13327 | H34: =+H5*Supuestos!$G$27 -> 10784.755 | I34: =+I5*Supuestos!$G$27 -> 11293.394 | J34: =+J5*Supuestos!$G$27 -> 11890.674
A35: Gasto Administración | B35: ='Gasto de Administración'!B11 -> 0 | C35: ='Gasto de Administración'!C11 -> 1684 | D35: ='Gasto de Administración'!D11 -> 2020 | E35: ='Gasto de Administración'!E11 -> 1810 | F35: ='Gasto de Administración'!F11 -> 1946 | G35: ='Gasto de Administración'!G11 -> 1946 | H35: =H33*Supuestos!$H$29 -> 1946 | I35: =I33*Supuestos!$H$29 -> 1946 | J35: =J33*Supuestos!$H$29 -> 1946
